<?xml version="1.0" ?>
<!-- Generated using onshape-to-robot -->
<!-- Onshape https://cad.onshape.com/documents/c2f8c0f4cc2871b1960725e5/w/daf1e303c611c75dfc5a7e94/e/7cd6a439cb18ac4e8dcaab42 -->
<robot name="my-robot">
  <!-- Link base_robot -->
  <link name="base_robot">
    <inertial>
      <origin xyz="0.013779 -0.150485 0.0208616" rpy="0 0 0"/>
      <mass value="3.67487"/>
      <inertia ixx="0.0132513" ixy="-0.000306371" ixz="-0.00232546" iyy="0.0129536" iyz="0.00145561" izz="0.0238105"/>
    </inertial>
    <!-- Part base_robot -->
    <visual>
      <origin xyz="0.0156403 -0.15165 0.0120183" rpy="-0.0175025 -0.242767 -0.486591"/>
      <geometry>
        <mesh filename="package://assets/base_robot.stl"/>
      </geometry>
      <material name="base_robot_material">
        <color rgba="0.615686 0.811765 0.929412 1.0"/>
      </material>
    </visual>
    <collision>
      <origin xyz="0.0156403 -0.15165 0.0120183" rpy="-0.0175025 -0.242767 -0.486591"/>
      <geometry>
        <mesh filename="package://assets/base_robot.stl"/>
      </geometry>
    </collision>
    <!-- Part 6204_part1 -->
    <visual>
      <origin xyz="0.0156403 -0.15165 0.0120183" rpy="-3.07104 -1.32741 2.58231"/>
      <geometry>
        <mesh filename="package://assets/6204_part1.stl"/>
      </geometry>
      <material name="6204_part1_material">
        <color rgba="1 0 0 1.0"/>
      </material>
    </visual>
    <collision>
      <origin xyz="0.0156403 -0.15165 0.0120183" rpy="-3.07104 -1.32741 2.58231"/>
      <geometry>
        <mesh filename="package://assets/6204_part1.stl"/>
      </geometry>
    </collision>
    <!-- Part 6204_part3 -->
    <visual>
      <origin xyz="0.0156403 -0.15165 0.0120183" rpy="0.855951 -1.32741 2.58231"/>
      <geometry>
        <mesh filename="package://assets/6204_part3.stl"/>
      </geometry>
      <material name="6204_part3_material">
        <color rgba="1 0 0 1.0"/>
      </material>
    </visual>
    <collision>
      <origin xyz="0.0156403 -0.15165 0.0120183" rpy="0.855951 -1.32741 2.58231"/>
      <geometry>
        <mesh filename="package://assets/6204_part3.stl"/>
      </geometry>
    </collision>
    <!-- Part 6204_part2 -->
    <visual>
      <origin xyz="0.0156403 -0.15165 0.0120183" rpy="-3.07104 -1.32741 2.58231"/>
      <geometry>
        <mesh filename="package://assets/6204_part2.stl"/>
      </geometry>
      <material name="6204_part2_material">
        <color rgba="1 0 0 1.0"/>
      </material>
    </visual>
    <collision>
      <origin xyz="0.0156403 -0.15165 0.0120183" rpy="-3.07104 -1.32741 2.58231"/>
      <geometry>
        <mesh filename="package://assets/6204_part2.stl"/>
      </geometry>
    </collision>
    <!-- Part 6204_part3_2 -->
    <visual>
      <origin xyz="0.0156403 -0.15165 0.0120183" rpy="1.64135 -1.32741 2.58231"/>
      <geometry>
        <mesh filename="package://assets/6204_part3.stl"/>
      </geometry>
      <material name="6204_part3_2_material">
        <color rgba="1 0 0 1.0"/>
      </material>
    </visual>
    <collision>
      <origin xyz="0.0156403 -0.15165 0.0120183" rpy="1.64135 -1.32741 2.58231"/>
      <geometry>
        <mesh filename="package://assets/6204_part3.stl"/>
      </geometry>
    </collision>
    <!-- Part 6204_part3_3 -->
    <visual>
      <origin xyz="0.0156403 -0.15165 0.0120183" rpy="-0.714845 -1.32741 2.58231"/>
      <geometry>
        <mesh filename="package://assets/6204_part3.stl"/>
      </geometry>
      <material name="6204_part3_3_material">
        <color rgba="1 0 0 1.0"/>
      </material>
    </visual>
    <collision>
      <origin xyz="0.0156403 -0.15165 0.0120183" rpy="-0.714845 -1.32741 2.58231"/>
      <geometry>
        <mesh filename="package://assets/6204_part3.stl"/>
      </geometry>
    </collision>
    <!-- Part 6204_part3_4 -->
    <visual>
      <origin xyz="0.0156403 -0.15165 0.0120183" rpy="2.42675 -1.32741 2.58231"/>
      <geometry>
        <mesh filename="package://assets/6204_part3.stl"/>
      </geometry>
      <material name="6204_part3_4_material">
        <color rgba="1 0 0 1.0"/>
      </material>
    </visual>
    <collision>
      <origin xyz="0.0156403 -0.15165 0.0120183" rpy="2.42675 -1.32741 2.58231"/>
      <geometry>
        <mesh filename="package://assets/6204_part3.stl"/>
      </geometry>
    </collision>
    <!-- Part 6204_part3_5 -->
    <visual>
      <origin xyz="0.0156403 -0.15165 0.0120183" rpy="-2.28564 -1.32741 2.58231"/>
      <geometry>
        <mesh filename="package://assets/6204_part3.stl"/>
      </geometry>
      <material name="6204_part3_5_material">
        <color rgba="1 0 0 1.0"/>
      </material>
    </visual>
    <collision>
      <origin xyz="0.0156403 -0.15165 0.0120183" rpy="-2.28564 -1.32741 2.58231"/>
      <geometry>
        <mesh filename="package://assets/6204_part3.stl"/>
      </geometry>
    </collision>
    <!-- Part 6204_part3_6 -->
    <visual>
      <origin xyz="0.0156403 -0.15165 0.0120183" rpy="-1.50024 -1.32741 2.58231"/>
      <geometry>
        <mesh filename="package://assets/6204_part3.stl"/>
      </geometry>
      <material name="6204_part3_6_material">
        <color rgba="1 0 0 1.0"/>
      </material>
    </visual>
    <collision>
      <origin xyz="0.0156403 -0.15165 0.0120183" rpy="-1.50024 -1.32741 2.58231"/>
      <geometry>
        <mesh filename="package://assets/6204_part3.stl"/>
      </geometry>
    </collision>
    <!-- Part 6204_part3_7 -->
    <visual>
      <origin xyz="0.0156403 -0.15165 0.0120183" rpy="-3.07104 -1.32741 2.58231"/>
      <geometry>
        <mesh filename="package://assets/6204_part3.stl"/>
      </geometry>
      <material name="6204_part3_7_material">
        <color rgba="1 0 0 1.0"/>
      </material>
    </visual>
    <collision>
      <origin xyz="0.0156403 -0.15165 0.0120183" rpy="-3.07104 -1.32741 2.58231"/>
      <geometry>
        <mesh filename="package://assets/6204_part3.stl"/>
      </geometry>
    </collision>
    <!-- Part 6204_part3_8 -->
    <visual>
      <origin xyz="0.0156403 -0.15165 0.0120183" rpy="0.0705531 -1.32741 2.58231"/>
      <geometry>
        <mesh filename="package://assets/6204_part3.stl"/>
      </geometry>
      <material name="6204_part3_8_material">
        <color rgba="1 0 0 1.0"/>
      </material>
    </visual>
    <collision>
      <origin xyz="0.0156403 -0.15165 0.0120183" rpy="0.0705531 -1.32741 2.58231"/>
      <geometry>
        <mesh filename="package://assets/6204_part3.stl"/>
      </geometry>
    </collision>
  </link>
  <!-- Link shaft_base -->
  <link name="shaft_base">
    <inertial>
      <origin xyz="-3.28529e-07 -3.75945e-07 -0.053835" rpy="0 0 0"/>
      <mass value="1.75339"/>
      <inertia ixx="0.00277843" ixy="-3.20777e-09" ixz="-4.41532e-09" iyy="0.00277843" iyz="-5.05258e-09" izz="0.00517343"/>
    </inertial>
    <!-- Part base_cover -->
    <visual>
      <origin xyz="-2.77556e-17 0 -0.0515" rpy="-3.14159 -5.98165e-15 1.09626e-16"/>
      <geometry>
        <mesh filename="package://assets/base_cover.stl"/>
      </geometry>
      <material name="base_cover_material">
        <color rgba="0.615686 0.811765 0.929412 1.0"/>
      </material>
    </visual>
    <collision>
      <origin xyz="-2.77556e-17 0 -0.0515" rpy="-3.14159 -5.98165e-15 1.09626e-16"/>
      <geometry>
        <mesh filename="package://assets/base_cover.stl"/>
      </geometry>
    </collision>
    <!-- Part shaft_base -->
    <visual>
      <origin xyz="-5.55112e-17 -2.77556e-17 -0.0705" rpy="5.96202e-15 5.14041e-16 -1.5708"/>
      <geometry>
        <mesh filename="package://assets/shaft_base.stl"/>
      </geometry>
      <material name="shaft_base_material">
        <color rgba="0.647059 0.647059 0.647059 1.0"/>
      </material>
    </visual>
    <collision>
      <origin xyz="-5.55112e-17 -2.77556e-17 -0.0705" rpy="5.96202e-15 5.14041e-16 -1.5708"/>
      <geometry>
        <mesh filename="package://assets/shaft_base.stl"/>
      </geometry>
    </collision>
  </link>
  <!-- Joint from base_robot to shaft_base -->
  <joint name="1revolute" type="revolute">
    <origin xyz="0.0135976 -0.150372 0.0217235" rpy="3.12409 -0.242767 -0.486591"/>
    <parent link="base_robot"/>
    <child link="shaft_base"/>
    <axis xyz="0 0 1"/>
    <limit effort="10" velocity="10" lower="169.646" upper="175.646"/>
  </joint>
</robot>
